2017-06-11 20:56:31 71714 INFO config - Using main config file: [[../../../config-common/user-sync-config-accessor.yml]]
2017-06-11 20:56:31 71714 INFO main - ========== Start Run (User Sync version: 2.1) ==============
2017-06-11 20:56:31 71714 INFO main - ------- Invocation parameters -------
2017-06-11 20:56:31 71714 INFO main - [[/Users/imak/github-adobe/user-sync.py/dist/user-sync --test-framework live -c ../../../config-common/user-sync-config-accessor.yml --users file ../../../config-common/users-accessors.csv]]
2017-06-11 20:56:31 71714 INFO main - -------------------------------------
2017-06-11 20:56:32 71714 INFO processor - ---------- Start Load from Directory -----------------------
2017-06-11 20:56:32 71714 WARNING csv - In file '[[../../../config-common/users-accessors.csv]]': unrecognized column names: ['bc', 'subco']
2017-06-11 20:56:32 71714 INFO processor - ---------- End Load from Directory (Total time: 0:00:00) ---
2017-06-11 20:56:32 71714 INFO processor - ---------- Start Sync Umapi --------------------------------
2017-06-11 20:58:33 71714 WARNING umapi.secondary.org1 - UMAPI connection timeout...(120 seconds on try 1)
Traceback (most recent call last):
  File "/usr/local/Cellar/python/2.7.10/Frameworks/Python.framework/Versions/2.7/lib/python2.7/logging/__init__.py", line 859, in emit
    msg = self.format(record)
  File "/usr/local/Cellar/python/2.7.10/Frameworks/Python.framework/Versions/2.7/lib/python2.7/logging/__init__.py", line 732, in format
    return fmt.format(record)
  File "/usr/local/Cellar/python/2.7.10/Frameworks/Python.framework/Versions/2.7/lib/python2.7/logging/__init__.py", line 471, in format
    record.message = record.getMessage()
  File "/usr/local/Cellar/python/2.7.10/Frameworks/Python.framework/Versions/2.7/lib/python2.7/logging/__init__.py", line 335, in getMessage
    msg = msg % self.args
TypeError: not all arguments converted during string formatting
Logged from file connection.py, line 426
2017-06-11 21:00:33 71714 WARNING umapi.secondary.org1 - UMAPI connection timeout...(120 seconds on try 2)
Traceback (most recent call last):
  File "/usr/local/Cellar/python/2.7.10/Frameworks/Python.framework/Versions/2.7/lib/python2.7/logging/__init__.py", line 859, in emit
    msg = self.format(record)
  File "/usr/local/Cellar/python/2.7.10/Frameworks/Python.framework/Versions/2.7/lib/python2.7/logging/__init__.py", line 732, in format
    return fmt.format(record)
  File "/usr/local/Cellar/python/2.7.10/Frameworks/Python.framework/Versions/2.7/lib/python2.7/logging/__init__.py", line 471, in format
    record.message = record.getMessage()
  File "/usr/local/Cellar/python/2.7.10/Frameworks/Python.framework/Versions/2.7/lib/python2.7/logging/__init__.py", line 335, in getMessage
    msg = msg % self.args
TypeError: not all arguments converted during string formatting
Logged from file connection.py, line 426
2017-06-11 21:02:33 71714 WARNING umapi.secondary.org1 - UMAPI connection timeout...(120 seconds on try 3)
Traceback (most recent call last):
  File "/usr/local/Cellar/python/2.7.10/Frameworks/Python.framework/Versions/2.7/lib/python2.7/logging/__init__.py", line 859, in emit
    msg = self.format(record)
  File "/usr/local/Cellar/python/2.7.10/Frameworks/Python.framework/Versions/2.7/lib/python2.7/logging/__init__.py", line 732, in format
    return fmt.format(record)
  File "/usr/local/Cellar/python/2.7.10/Frameworks/Python.framework/Versions/2.7/lib/python2.7/logging/__init__.py", line 471, in format
    record.message = record.getMessage()
  File "/usr/local/Cellar/python/2.7.10/Frameworks/Python.framework/Versions/2.7/lib/python2.7/logging/__init__.py", line 335, in getMessage
    msg = msg % self.args
TypeError: not all arguments converted during string formatting
Logged from file connection.py, line 426
2017-06-11 21:04:33 71714 WARNING umapi.secondary.org1 - UMAPI connection timeout...(120 seconds on try 4)
2017-06-11 21:04:33 71714 ERROR umapi.secondary.org1 - UMAPI timeout...giving up after 4 attempts (480 seconds).
2017-06-11 21:04:33 71714 ERROR main - Unhandled exception
Traceback (most recent call last):
  File "/Users/imak/github-adobe/user-sync.py/user_sync/app.py", line 362, in main
    begin_work(config_loader)
  File "/Users/imak/github-adobe/user-sync.py/user_sync/app.py", line 216, in begin_work
    rule_processor.run(directory_groups, directory_connector, umapi_connectors)
  File "/Users/imak/github-adobe/user-sync.py/user_sync/rules.py", line 166, in run
    self.process_umapi_users(umapi_connectors)
  File "/Users/imak/github-adobe/user-sync.py/user_sync/rules.py", line 402, in process_umapi_users
    secondary_updates_by_user_key = self.update_umapi_users_for_connector(secondary_umapi_info, umapi_connector)
  File "/Users/imak/github-adobe/user-sync.py/user_sync/rules.py", line 711, in update_umapi_users_for_connector
    for umapi_user in umapi_connector.iter_users():
  File "/Users/imak/github-adobe/user-sync.py/user_sync/connector/umapi.py", line 143, in iter_users
    for u in umapi_client.UsersQuery(self.connection):
  File "/Users/imak/.pex/install/umapi_client-2.5-py2.py3-none-any.whl.141b6aa0123ab047aadb799c132f52db57be9bd9/umapi_client-2.5-py2.py3-none-any.whl/umapi_client/api.py", line 197, in next
    return self.query._next_item()
  File "/Users/imak/.pex/install/umapi_client-2.5-py2.py3-none-any.whl.141b6aa0123ab047aadb799c132f52db57be9bd9/umapi_client-2.5-py2.py3-none-any.whl/umapi_client/api.py", line 181, in _next_item
    self._next_page()
  File "/Users/imak/.pex/install/umapi_client-2.5-py2.py3-none-any.whl.141b6aa0123ab047aadb799c132f52db57be9bd9/umapi_client-2.5-py2.py3-none-any.whl/umapi_client/api.py", line 172, in _next_page
    self.url_params, self.query_params)
  File "/Users/imak/.pex/install/umapi_client-2.5-py2.py3-none-any.whl.141b6aa0123ab047aadb799c132f52db57be9bd9/umapi_client-2.5-py2.py3-none-any.whl/umapi_client/connection.py", line 238, in query_multiple
    result = self.make_call(query_path)
  File "/Users/imak/.pex/install/umapi_client-2.5-py2.py3-none-any.whl.141b6aa0123ab047aadb799c132f52db57be9bd9/umapi_client-2.5-py2.py3-none-any.whl/umapi_client/connection.py", line 429, in make_call
    raise UnavailableError(self.retry_max_attempts, total_time, result)
UnavailableError: Server unavailable: Made 4 attempts over 480 seconds
2017-06-11 21:04:33 71714 INFO main - ========== End Run (User Sync version: 2.1) (Total time: 0:08:02) 
